2024-04-09 19:21:16,649 DEBUG    root            Loaded Command Group: ['gcloud', 'projects']
2024-04-09 19:21:16,651 DEBUG    root            Loaded Command Group: ['gcloud', 'projects', 'describe']
2024-04-09 19:21:16,652 DEBUG    root            Running [gcloud.projects.describe] with arguments: [--account: "hardiksharmah73@gmail.com", --configuration: "default", --format: "value(name)", PROJECT_ID_OR_NUMBER: "pegasus-401519"]
2024-04-09 19:21:16,673 DEBUG    google.auth.transport.requests Making request: POST https://oauth2.googleapis.com/token
2024-04-09 19:21:16,675 DEBUG    urllib3.connectionpool Starting new HTTPS connection (1): oauth2.googleapis.com:443
2024-04-09 19:21:16,675 DEBUG    google.auth.transport.requests Making request: POST https://oauth2.googleapis.com/token
2024-04-09 19:21:16,676 DEBUG    urllib3.connectionpool Starting new HTTPS connection (2): oauth2.googleapis.com:443
2024-04-09 19:21:16,677 DEBUG    root            (gcloud.projects.describe) There was a problem refreshing your current auth tokens: HTTPSConnectionPool(host='oauth2.googleapis.com', port=443): Max retries exceeded with url: /token (Caused by NewConnectionError('<urllib3.connection.HTTPSConnection object at 0x7ff9f92e8a90>: Failed to establish a new connection: [Errno -3] Temporary failure in name resolution',))
Please run:

  $ gcloud auth login

to obtain new credentials.

If you have already logged in with a different account, run:

  $ gcloud config set account ACCOUNT

to select an already authenticated account to use.
Traceback (most recent call last):
  File "/home/devilunraveled/GoogleCloud/google-cloud-sdk/lib/third_party/urllib3/connection.py", line 175, in _new_conn
    (self._dns_host, self.port), self.timeout, **extra_kw
  File "/home/devilunraveled/GoogleCloud/google-cloud-sdk/lib/third_party/urllib3/util/connection.py", line 72, in create_connection
    for res in socket.getaddrinfo(host, port, family, socket.SOCK_STREAM):
  File "/home/devilunraveled/.pyenv/versions/3.6.15/lib/python3.6/socket.py", line 745, in getaddrinfo
    for res in _socket.getaddrinfo(host, port, family, type, proto, flags):
socket.gaierror: [Errno -3] Temporary failure in name resolution

During handling of the above exception, another exception occurred:

Traceback (most recent call last):
  File "/home/devilunraveled/GoogleCloud/google-cloud-sdk/lib/third_party/urllib3/connectionpool.py", line 724, in urlopen
    chunked=chunked,
  File "/home/devilunraveled/GoogleCloud/google-cloud-sdk/lib/third_party/urllib3/connectionpool.py", line 406, in _make_request
    self._validate_conn(conn)
  File "/home/devilunraveled/GoogleCloud/google-cloud-sdk/lib/third_party/urllib3/connectionpool.py", line 1057, in _validate_conn
    conn.connect()
  File "/home/devilunraveled/GoogleCloud/google-cloud-sdk/lib/third_party/urllib3/connection.py", line 358, in connect
    self.sock = conn = self._new_conn()
  File "/home/devilunraveled/GoogleCloud/google-cloud-sdk/lib/third_party/urllib3/connection.py", line 187, in _new_conn
    self, "Failed to establish a new connection: %s" % e
urllib3.exceptions.NewConnectionError: <urllib3.connection.HTTPSConnection object at 0x7ff9f92e8a90>: Failed to establish a new connection: [Errno -3] Temporary failure in name resolution

During handling of the above exception, another exception occurred:

Traceback (most recent call last):
  File "/home/devilunraveled/GoogleCloud/google-cloud-sdk/lib/third_party/requests/adapters.py", line 449, in send
    timeout=timeout
  File "/home/devilunraveled/GoogleCloud/google-cloud-sdk/lib/third_party/urllib3/connectionpool.py", line 800, in urlopen
    method, url, error=e, _pool=self, _stacktrace=sys.exc_info()[2]
  File "/home/devilunraveled/GoogleCloud/google-cloud-sdk/lib/third_party/urllib3/util/retry.py", line 592, in increment
    raise MaxRetryError(_pool, url, error or ResponseError(cause))
urllib3.exceptions.MaxRetryError: HTTPSConnectionPool(host='oauth2.googleapis.com', port=443): Max retries exceeded with url: /token (Caused by NewConnectionError('<urllib3.connection.HTTPSConnection object at 0x7ff9f92e8a90>: Failed to establish a new connection: [Errno -3] Temporary failure in name resolution',))

During handling of the above exception, another exception occurred:

Traceback (most recent call last):
  File "/home/devilunraveled/GoogleCloud/google-cloud-sdk/lib/third_party/google/auth/transport/requests.py", line 194, in __call__
    method, url, data=body, headers=headers, timeout=timeout, **kwargs
  File "/home/devilunraveled/GoogleCloud/google-cloud-sdk/lib/googlecloudsdk/core/transport.py", line 258, in WrappedRequest
    response = orig_request(*modified_args, **modified_kwargs)
  File "/home/devilunraveled/GoogleCloud/google-cloud-sdk/lib/googlecloudsdk/core/requests.py", line 246, in WrappedRequest
    return orig_request_method(*args, **kwargs)
  File "/home/devilunraveled/GoogleCloud/google-cloud-sdk/lib/third_party/requests/sessions.py", line 544, in request
    resp = self.send(prep, **send_kwargs)
  File "/home/devilunraveled/GoogleCloud/google-cloud-sdk/lib/third_party/requests/sessions.py", line 657, in send
    r = adapter.send(request, **kwargs)
  File "/home/devilunraveled/GoogleCloud/google-cloud-sdk/lib/third_party/requests/adapters.py", line 516, in send
    raise ConnectionError(e, request=request)
requests.exceptions.ConnectionError: HTTPSConnectionPool(host='oauth2.googleapis.com', port=443): Max retries exceeded with url: /token (Caused by NewConnectionError('<urllib3.connection.HTTPSConnection object at 0x7ff9f92e8a90>: Failed to establish a new connection: [Errno -3] Temporary failure in name resolution',))

The above exception was the direct cause of the following exception:

Traceback (most recent call last):
  File "/home/devilunraveled/GoogleCloud/google-cloud-sdk/lib/googlecloudsdk/calliope/cli.py", line 987, in Execute
    resources = calliope_command.Run(cli=self, args=args)
  File "/home/devilunraveled/GoogleCloud/google-cloud-sdk/lib/googlecloudsdk/calliope/backend.py", line 807, in Run
    resources = command_instance.Run(args)
  File "/home/devilunraveled/GoogleCloud/google-cloud-sdk/lib/surface/projects/describe.py", line 51, in Run
    return projects_api.Get(project_ref)
  File "/home/devilunraveled/GoogleCloud/google-cloud-sdk/lib/googlecloudsdk/api_lib/cloudresourcemanager/projects_api.py", line 124, in Get
    client = projects_util.GetClient(api_version)
  File "/home/devilunraveled/GoogleCloud/google-cloud-sdk/lib/googlecloudsdk/api_lib/cloudresourcemanager/projects_util.py", line 56, in GetClient
    return apis.GetClientInstance(_API_NAME, version)
  File "/home/devilunraveled/GoogleCloud/google-cloud-sdk/lib/googlecloudsdk/api_lib/util/apis.py", line 271, in GetClientInstance
    http_timeout_sec=http_timeout_sec,
  File "/home/devilunraveled/GoogleCloud/google-cloud-sdk/lib/googlecloudsdk/api_lib/util/apis_internal.py", line 171, in _GetClientInstance
    timeout=http_timeout_sec if http_timeout_sec else 'unset')
  File "/home/devilunraveled/GoogleCloud/google-cloud-sdk/lib/googlecloudsdk/core/credentials/transports.py", line 86, in GetApitoolsTransport
    redact_request_body_reason=redact_request_body_reason)
  File "/home/devilunraveled/GoogleCloud/google-cloud-sdk/lib/googlecloudsdk/core/credentials/requests.py", line 83, in GetSession
    allow_account_impersonation, True)
  File "/home/devilunraveled/GoogleCloud/google-cloud-sdk/lib/googlecloudsdk/core/credentials/requests.py", line 129, in WrapQuota
    use_google_auth)
  File "/home/devilunraveled/GoogleCloud/google-cloud-sdk/lib/googlecloudsdk/core/credentials/transport.py", line 54, in QuotaProject
    creds = store.LoadIfEnabled(allow_account_impersonation, use_google_auth)
  File "/home/devilunraveled/GoogleCloud/google-cloud-sdk/lib/googlecloudsdk/core/credentials/store.py", line 458, in LoadIfEnabled
    use_google_auth=use_google_auth)
  File "/home/devilunraveled/GoogleCloud/google-cloud-sdk/lib/googlecloudsdk/core/credentials/store.py", line 571, in Load
    with_access_token_cache=with_access_token_cache)
  File "/home/devilunraveled/GoogleCloud/google-cloud-sdk/lib/googlecloudsdk/core/credentials/store.py", line 748, in _Load
    RefreshIfAlmostExpire(cred)
  File "/home/devilunraveled/GoogleCloud/google-cloud-sdk/lib/googlecloudsdk/core/credentials/store.py", line 1069, in RefreshIfAlmostExpire
    RefreshIfExpireWithinWindow(credentials, window=_CREDENTIALS_EXPIRY_WINDOW)
  File "/home/devilunraveled/GoogleCloud/google-cloud-sdk/lib/googlecloudsdk/core/credentials/store.py", line 1065, in RefreshIfExpireWithinWindow
    Refresh(credentials)
  File "/home/devilunraveled/GoogleCloud/google-cloud-sdk/lib/googlecloudsdk/core/credentials/store.py", line 789, in Refresh
    include_email, gce_token_format, gce_include_license)
  File "/home/devilunraveled/GoogleCloud/google-cloud-sdk/lib/googlecloudsdk/core/credentials/store.py", line 960, in _RefreshGoogleAuth
    credentials.refresh(request_client)
  File "/home/devilunraveled/GoogleCloud/google-cloud-sdk/lib/googlecloudsdk/core/credentials/creds.py", line 641, in _WrappedRefresh
    orig_refresh(request)
  File "/home/devilunraveled/GoogleCloud/google-cloud-sdk/lib/googlecloudsdk/core/credentials/google_auth_credentials.py", line 105, in refresh
    return self._Refresh(request)
  File "/home/devilunraveled/GoogleCloud/google-cloud-sdk/lib/googlecloudsdk/core/credentials/google_auth_credentials.py", line 152, in _Refresh
    self._client_secret, self._scopes, rapt_token)
  File "/home/devilunraveled/GoogleCloud/google-cloud-sdk/lib/googlecloudsdk/core/credentials/google_auth_credentials.py", line 245, in _RefreshGrant
    response_data = _TokenEndpointRequestWithRetry(request, token_uri, body)
  File "/home/devilunraveled/GoogleCloud/google-cloud-sdk/lib/googlecloudsdk/core/util/retry.py", line 312, in DecoratedFunction
    exceptions.reraise(to_reraise[1], tb=to_reraise[2])
  File "/home/devilunraveled/GoogleCloud/google-cloud-sdk/lib/googlecloudsdk/core/exceptions.py", line 146, in reraise
    six.reraise(type(exc_value), exc_value, tb)
  File "/home/devilunraveled/GoogleCloud/google-cloud-sdk/lib/third_party/six/__init__.py", line 719, in reraise
    raise value
  File "/home/devilunraveled/GoogleCloud/google-cloud-sdk/lib/googlecloudsdk/core/util/retry.py", line 182, in TryFunc
    return func(*args, **kwargs), None
  File "/home/devilunraveled/GoogleCloud/google-cloud-sdk/lib/googlecloudsdk/core/credentials/google_auth_credentials.py", line 301, in _TokenEndpointRequestWithRetry
    response = request(method='POST', url=token_uri, headers=headers, body=body)
  File "/home/devilunraveled/GoogleCloud/google-cloud-sdk/lib/third_party/google/auth/transport/requests.py", line 199, in __call__
    six.raise_from(new_exc, caught_exc)
  File "<string>", line 3, in raise_from
google.auth.exceptions.TransportError: HTTPSConnectionPool(host='oauth2.googleapis.com', port=443): Max retries exceeded with url: /token (Caused by NewConnectionError('<urllib3.connection.HTTPSConnection object at 0x7ff9f92e8a90>: Failed to establish a new connection: [Errno -3] Temporary failure in name resolution',))
2024-04-09 19:21:16,684 ERROR    root            (gcloud.projects.describe) There was a problem refreshing your current auth tokens: HTTPSConnectionPool(host='oauth2.googleapis.com', port=443): Max retries exceeded with url: /token (Caused by NewConnectionError('<urllib3.connection.HTTPSConnection object at 0x7ff9f92e8a90>: Failed to establish a new connection: [Errno -3] Temporary failure in name resolution',))
Please run:

  $ gcloud auth login

to obtain new credentials.

If you have already logged in with a different account, run:

  $ gcloud config set account ACCOUNT

to select an already authenticated account to use.
