2023-10-10 01:20:20,794 DEBUG    root            Loaded Command Group: ['gcloud', 'init']
2023-10-10 01:20:20,796 DEBUG    root            Running [gcloud.init] with arguments: []
2023-10-10 01:20:20,796 INFO     ___FILE_ONLY___ Welcome! This command will take you through the configuration of gcloud.


2023-10-10 01:20:20,797 INFO     ___FILE_ONLY___ Your current configuration has been set to: [default]


2023-10-10 01:20:20,797 INFO     ___FILE_ONLY___ You can skip diagnostics next time by using the following flag:

2023-10-10 01:20:20,797 INFO     ___FILE_ONLY___   gcloud init --skip-diagnostics


2023-10-10 01:20:20,797 INFO     ___FILE_ONLY___ Network diagnostic detects and fixes local network connection issues.

2023-10-10 01:20:20,797 INFO     ___FILE_ONLY___ Checking network connection...
2023-10-10 01:20:23,279 DEBUG    urllib3.connectionpool Starting new HTTPS connection (1): accounts.google.com:443
2023-10-10 01:20:23,425 DEBUG    urllib3.connectionpool https://accounts.google.com:443 "GET / HTTP/1.1" 302 338
2023-10-10 01:20:23,623 DEBUG    urllib3.connectionpool https://accounts.google.com:443 "GET /ServiceLogin?passive=1209600&continue=https%3A%2F%2Faccounts.google.com%2F&followup=https%3A%2F%2Faccounts.google.com%2F HTTP/1.1" 302 0
2023-10-10 01:20:23,702 DEBUG    urllib3.connectionpool https://accounts.google.com:443 "GET /InteractiveLogin?continue=https://accounts.google.com/&followup=https://accounts.google.com/&passive=1209600&ifkv=AYZoVhc5o6CbIW-5T1MPtQRUlm7TMYDXt5U6axxCHIT1jZMcDJSgmXdDyJGKgFZrdCxsS_EZG_o_lQ HTTP/1.1" 302 525
2023-10-10 01:20:23,882 DEBUG    urllib3.connectionpool https://accounts.google.com:443 "GET /v3/signin/identifier?continue=https%3A%2F%2Faccounts.google.com%2F&followup=https%3A%2F%2Faccounts.google.com%2F&ifkv=AYZoVhfbol2P3SdRYm0sFiKar6x_dtstqCj2RpDf_dXJ8TXzSO-if-VZGM01rZ5cHbMQOXcLV2wrxg&passive=1209600&flowName=WebLiteSignIn&flowEntry=ServiceLogin&dsh=S67368620%3A1696881023650144 HTTP/1.1" 200 None
2023-10-10 01:20:23,994 DEBUG    urllib3.connectionpool Starting new HTTPS connection (1): cloudresourcemanager.googleapis.com:443
2023-10-10 01:20:25,196 DEBUG    urllib3.connectionpool https://cloudresourcemanager.googleapis.com:443 "GET /v1beta1/projects HTTP/1.1" 401 None
2023-10-10 01:20:25,202 DEBUG    urllib3.connectionpool Starting new HTTPS connection (1): www.googleapis.com:443
2023-10-10 01:20:25,333 DEBUG    urllib3.connectionpool https://www.googleapis.com:443 "GET /auth/cloud-platform HTTP/1.1" 200 14
2023-10-10 01:20:25,339 DEBUG    urllib3.connectionpool Starting new HTTPS connection (1): dl.google.com:443
2023-10-10 01:20:25,479 DEBUG    urllib3.connectionpool https://dl.google.com:443 "GET /dl/cloudsdk/channels/rapid/components-2.json HTTP/1.1" 200 209942
2023-10-10 01:20:25,609 INFO     ___FILE_ONLY___ Reachability Check passed.

2023-10-10 01:20:25,609 INFO     ___FILE_ONLY___ Network diagnostic passed (1/1 checks passed).


2023-10-10 01:20:36,925 DEBUG    root            Loaded Command Group: ['gcloud', 'auth']
2023-10-10 01:20:36,937 DEBUG    root            Loaded Command Group: ['gcloud', 'auth', 'login']
2023-10-10 01:20:36,938 INFO     root            Executing: [gcloud auth login --force --brief]
2023-10-10 01:20:36,939 DEBUG    root            Running [gcloud.auth.login] with arguments: [--brief: "True", --force: "True"]
2023-10-10 01:20:37,284 DEBUG    requests_oauthlib.oauth2_session Generated new state bSHEffSeS3J1TQpHF9PAIKD1Wpwfgo.
2023-10-10 01:37:43,466 INFO     ___FILE_ONLY___ Your browser has been opened to visit:

    https://accounts.google.com/o/oauth2/auth?response_type=code&client_id=32555940559.apps.googleusercontent.com&redirect_uri=http%3A%2F%2Flocalhost%3A8085%2F&scope=openid+https%3A%2F%2Fwww.googleapis.com%2Fauth%2Fuserinfo.email+https%3A%2F%2Fwww.googleapis.com%2Fauth%2Fcloud-platform+https%3A%2F%2Fwww.googleapis.com%2Fauth%2Fappengine.admin+https%3A%2F%2Fwww.googleapis.com%2Fauth%2Fsqlservice.login+https%3A%2F%2Fwww.googleapis.com%2Fauth%2Fcompute+https%3A%2F%2Fwww.googleapis.com%2Fauth%2Faccounts.reauth&state=bSHEffSeS3J1TQpHF9PAIKD1Wpwfgo&access_type=offline&code_challenge=5tjiVZlv1hXUw2zXP78vcvlS2_N7StpSeDxBCATWlkM&code_challenge_method=S256


2023-10-10 01:37:43,469 DEBUG    requests_oauthlib.oauth2_session Requesting url https://oauth2.googleapis.com/token using method POST.
2023-10-10 01:37:43,469 DEBUG    requests_oauthlib.oauth2_session Supplying headers {b'Accept': b'application/json', b'Content-Type': b'application/x-www-form-urlencoded;charset=UTF-8', b'user-agent': b'google-cloud-sdk gcloud/449.0.0 command/gcloud.auth.login invocation-id/d2b36814640f44788654d26cc5cc462e environment/None environment-version/None client-os/LINUX client-os-ver/5.15.131 client-pltf-arch/x86_64 interactive/True from-script/False python/3.10.10 term/xterm-kitty (Linux 5.15.131-1-MANJARO)'} and data {'grant_type': 'authorization_code', 'client_id': '32555940559.apps.googleusercontent.com', 'client_secret': 'ZmssLNjJy2998hD4CTg2ejr2', 'code': '4/0AfJohXl6W4oywt3wMdDmQ6yUwpTKpwg4_lCf96Eu7sOIT08IDeY5fjhLaJAppDlld3Ywiw', 'redirect_uri': 'http://localhost:8085/', 'code_verifier': '2w9zudP8jvgse9DmkIHOGb77rwugbx.IKqancAIgGppz1y59ywXtdiHlqB8tilz81wQYhMpW6n.d6pZB_ohIUZrQGSuTruMG4A8cq6sawp82~MIuvgvguyicrLkHCb0.'}
2023-10-10 01:37:43,469 DEBUG    requests_oauthlib.oauth2_session Passing through key word arguments {'json': None, 'timeout': None, 'auth': None, 'verify': None, 'proxies': None}.
2023-10-10 01:37:43,471 DEBUG    urllib3.connectionpool Starting new HTTPS connection (1): oauth2.googleapis.com:443
2023-10-10 01:37:43,617 DEBUG    urllib3.connectionpool https://oauth2.googleapis.com:443 "POST /token HTTP/1.1" 400 None
2023-10-10 01:37:43,618 DEBUG    requests_oauthlib.oauth2_session Prepared fetch token request body grant_type=authorization_code&client_id=32555940559.apps.googleusercontent.com&client_secret=ZmssLNjJy2998hD4CTg2ejr2&code=4%2F0AfJohXl6W4oywt3wMdDmQ6yUwpTKpwg4_lCf96Eu7sOIT08IDeY5fjhLaJAppDlld3Ywiw&redirect_uri=http%3A%2F%2Flocalhost%3A8085%2F&code_verifier=2w9zudP8jvgse9DmkIHOGb77rwugbx.IKqancAIgGppz1y59ywXtdiHlqB8tilz81wQYhMpW6n.d6pZB_ohIUZrQGSuTruMG4A8cq6sawp82~MIuvgvguyicrLkHCb0.
2023-10-10 01:37:43,619 DEBUG    requests_oauthlib.oauth2_session Request to fetch token completed with status 400.
2023-10-10 01:37:43,619 DEBUG    requests_oauthlib.oauth2_session Request headers were {'user-agent': b'google-cloud-sdk gcloud/449.0.0 command/gcloud.auth.login invocation-id/d2b36814640f44788654d26cc5cc462e environment/None environment-version/None client-os/LINUX client-os-ver/5.15.131 client-pltf-arch/x86_64 interactive/True from-script/False python/3.10.10 term/xterm-kitty (Linux 5.15.131-1-MANJARO)', 'Accept-Encoding': 'gzip, deflate', 'Accept': b'application/json', 'Connection': 'keep-alive', 'Content-Type': b'application/x-www-form-urlencoded;charset=UTF-8', 'Content-Length': '387'}
2023-10-10 01:37:43,619 DEBUG    requests_oauthlib.oauth2_session Request body was grant_type=authorization_code&client_id=32555940559.apps.googleusercontent.com&client_secret=ZmssLNjJy2998hD4CTg2ejr2&code=4%2F0AfJohXl6W4oywt3wMdDmQ6yUwpTKpwg4_lCf96Eu7sOIT08IDeY5fjhLaJAppDlld3Ywiw&redirect_uri=http%3A%2F%2Flocalhost%3A8085%2F&code_verifier=2w9zudP8jvgse9DmkIHOGb77rwugbx.IKqancAIgGppz1y59ywXtdiHlqB8tilz81wQYhMpW6n.d6pZB_ohIUZrQGSuTruMG4A8cq6sawp82~MIuvgvguyicrLkHCb0.
2023-10-10 01:37:43,619 DEBUG    requests_oauthlib.oauth2_session Response headers were {'Expires': 'Mon, 01 Jan 1990 00:00:00 GMT', 'Pragma': 'no-cache', 'Date': 'Mon, 09 Oct 2023 20:07:43 GMT', 'Cache-Control': 'no-cache, no-store, max-age=0, must-revalidate', 'Content-Type': 'application/json; charset=utf-8', 'Vary': 'Origin, X-Origin, Referer', 'Content-Encoding': 'gzip', 'Server': 'scaffolding on HTTPServer2', 'X-XSS-Protection': '0', 'X-Frame-Options': 'SAMEORIGIN', 'X-Content-Type-Options': 'nosniff', 'Alt-Svc': 'h3=":443"; ma=2592000,h3-29=":443"; ma=2592000', 'Transfer-Encoding': 'chunked'} and content {
  "error": "invalid_grant",
  "error_description": "Bad Request"
}.
2023-10-10 01:37:43,619 DEBUG    requests_oauthlib.oauth2_session Invoking 0 token response hooks.
2023-10-10 01:37:43,619 DEBUG    root            (invalid_grant) Bad Request
Traceback (most recent call last):
  File "/home/devilunraveled/GoogleCloud/google-cloud-sdk/lib/googlecloudsdk/calliope/cli.py", line 987, in Execute
    resources = calliope_command.Run(cli=self, args=args)
  File "/home/devilunraveled/GoogleCloud/google-cloud-sdk/lib/googlecloudsdk/calliope/backend.py", line 807, in Run
    resources = command_instance.Run(args)
  File "/home/devilunraveled/GoogleCloud/google-cloud-sdk/lib/surface/auth/login.py", line 331, in Run
    creds = auth_util.DoInstalledAppBrowserFlowGoogleAuth(
  File "/home/devilunraveled/GoogleCloud/google-cloud-sdk/lib/googlecloudsdk/api_lib/auth/util.py", line 332, in DoInstalledAppBrowserFlowGoogleAuth
    user_creds = BrowserFlowWithNoBrowserFallbackRunner(
  File "/home/devilunraveled/GoogleCloud/google-cloud-sdk/lib/googlecloudsdk/api_lib/auth/util.py", line 144, in Run
    return self._flow.Run(**kwargs)
  File "/home/devilunraveled/GoogleCloud/google-cloud-sdk/lib/googlecloudsdk/core/credentials/flow.py", line 237, in Run
    return self._Run(**kwargs)
  File "/home/devilunraveled/GoogleCloud/google-cloud-sdk/lib/googlecloudsdk/core/credentials/flow.py", line 336, in _Run
    self.fetch_token(
  File "/home/devilunraveled/GoogleCloud/google-cloud-sdk/lib/third_party/google_auth_oauthlib/flow.py", line 300, in fetch_token
    return self.oauth2session.fetch_token(self.client_config["token_uri"], **kwargs)
  File "/home/devilunraveled/GoogleCloud/google-cloud-sdk/lib/third_party/requests_oauthlib/oauth2_session.py", line 345, in fetch_token
    self._client.parse_request_body_response(r.text, scope=self.scope)
  File "/home/devilunraveled/GoogleCloud/google-cloud-sdk/lib/third_party/oauthlib/oauth2/rfc6749/clients/base.py", line 451, in parse_request_body_response
    self.token = parse_token_response(body, scope=scope)
  File "/home/devilunraveled/GoogleCloud/google-cloud-sdk/lib/third_party/oauthlib/oauth2/rfc6749/parameters.py", line 435, in parse_token_response
    validate_token_parameters(params)
  File "/home/devilunraveled/GoogleCloud/google-cloud-sdk/lib/third_party/oauthlib/oauth2/rfc6749/parameters.py", line 442, in validate_token_parameters
    raise_from_error(params.get('error'), params)
  File "/home/devilunraveled/GoogleCloud/google-cloud-sdk/lib/third_party/oauthlib/oauth2/rfc6749/errors.py", line 406, in raise_from_error
    raise cls(**kwargs)
oauthlib.oauth2.rfc6749.errors.InvalidGrantError: (invalid_grant) Bad Request
2023-10-10 01:37:43,630 INFO     root            Failed to run [auth login --force --brief]

2023-10-10 01:37:43,630 DEBUG    root            (invalid_grant) Bad Request
Traceback (most recent call last):
  File "/home/devilunraveled/GoogleCloud/google-cloud-sdk/lib/googlecloudsdk/calliope/cli.py", line 987, in Execute
    resources = calliope_command.Run(cli=self, args=args)
  File "/home/devilunraveled/GoogleCloud/google-cloud-sdk/lib/googlecloudsdk/calliope/backend.py", line 807, in Run
    resources = command_instance.Run(args)
  File "/home/devilunraveled/GoogleCloud/google-cloud-sdk/lib/surface/init.py", line 160, in Run
    if not self._PickAccount(
  File "/home/devilunraveled/GoogleCloud/google-cloud-sdk/lib/surface/init.py", line 232, in _PickAccount
    if not self._RunCmd(['auth', 'login'],
  File "/home/devilunraveled/GoogleCloud/google-cloud-sdk/lib/surface/init.py", line 525, in _RunCmd
    self.ExecuteCommandDoNotUse(args))
  File "/home/devilunraveled/GoogleCloud/google-cloud-sdk/lib/googlecloudsdk/calliope/base.py", line 624, in ExecuteCommandDoNotUse
    return self._cli_power_users_only.Execute(args, call_arg_complete=False)
  File "/home/devilunraveled/GoogleCloud/google-cloud-sdk/lib/googlecloudsdk/calliope/cli.py", line 1013, in Execute
    self._HandleAllErrors(exc, command_path_string, specified_arg_names)
  File "/home/devilunraveled/GoogleCloud/google-cloud-sdk/lib/googlecloudsdk/calliope/cli.py", line 1050, in _HandleAllErrors
    exceptions.HandleError(exc, command_path_string, self.__known_error_handler)
  File "/home/devilunraveled/GoogleCloud/google-cloud-sdk/lib/googlecloudsdk/calliope/exceptions.py", line 557, in HandleError
    core_exceptions.reraise(exc)
  File "/home/devilunraveled/GoogleCloud/google-cloud-sdk/lib/googlecloudsdk/core/exceptions.py", line 146, in reraise
    six.reraise(type(exc_value), exc_value, tb)
  File "/home/devilunraveled/GoogleCloud/google-cloud-sdk/lib/third_party/six/__init__.py", line 719, in reraise
    raise value
  File "/home/devilunraveled/GoogleCloud/google-cloud-sdk/lib/googlecloudsdk/calliope/cli.py", line 987, in Execute
    resources = calliope_command.Run(cli=self, args=args)
  File "/home/devilunraveled/GoogleCloud/google-cloud-sdk/lib/googlecloudsdk/calliope/backend.py", line 807, in Run
    resources = command_instance.Run(args)
  File "/home/devilunraveled/GoogleCloud/google-cloud-sdk/lib/surface/auth/login.py", line 331, in Run
    creds = auth_util.DoInstalledAppBrowserFlowGoogleAuth(
  File "/home/devilunraveled/GoogleCloud/google-cloud-sdk/lib/googlecloudsdk/api_lib/auth/util.py", line 332, in DoInstalledAppBrowserFlowGoogleAuth
    user_creds = BrowserFlowWithNoBrowserFallbackRunner(
  File "/home/devilunraveled/GoogleCloud/google-cloud-sdk/lib/googlecloudsdk/api_lib/auth/util.py", line 144, in Run
    return self._flow.Run(**kwargs)
  File "/home/devilunraveled/GoogleCloud/google-cloud-sdk/lib/googlecloudsdk/core/credentials/flow.py", line 237, in Run
    return self._Run(**kwargs)
  File "/home/devilunraveled/GoogleCloud/google-cloud-sdk/lib/googlecloudsdk/core/credentials/flow.py", line 336, in _Run
    self.fetch_token(
  File "/home/devilunraveled/GoogleCloud/google-cloud-sdk/lib/third_party/google_auth_oauthlib/flow.py", line 300, in fetch_token
    return self.oauth2session.fetch_token(self.client_config["token_uri"], **kwargs)
  File "/home/devilunraveled/GoogleCloud/google-cloud-sdk/lib/third_party/requests_oauthlib/oauth2_session.py", line 345, in fetch_token
    self._client.parse_request_body_response(r.text, scope=self.scope)
  File "/home/devilunraveled/GoogleCloud/google-cloud-sdk/lib/third_party/oauthlib/oauth2/rfc6749/clients/base.py", line 451, in parse_request_body_response
    self.token = parse_token_response(body, scope=scope)
  File "/home/devilunraveled/GoogleCloud/google-cloud-sdk/lib/third_party/oauthlib/oauth2/rfc6749/parameters.py", line 435, in parse_token_response
    validate_token_parameters(params)
  File "/home/devilunraveled/GoogleCloud/google-cloud-sdk/lib/third_party/oauthlib/oauth2/rfc6749/parameters.py", line 442, in validate_token_parameters
    raise_from_error(params.get('error'), params)
  File "/home/devilunraveled/GoogleCloud/google-cloud-sdk/lib/third_party/oauthlib/oauth2/rfc6749/errors.py", line 406, in raise_from_error
    raise cls(**kwargs)
oauthlib.oauth2.rfc6749.errors.InvalidGrantError: (invalid_grant) Bad Request
2023-10-10 01:37:43,631 ERROR    ___FILE_ONLY___ BEGIN CRASH STACKTRACE
Traceback (most recent call last):
  File "/home/devilunraveled/GoogleCloud/google-cloud-sdk/lib/googlecloudsdk/command_lib/crash_handling.py", line 199, in Wrapper
    target_function(*args, **kwargs)
  File "/home/devilunraveled/GoogleCloud/google-cloud-sdk/lib/googlecloudsdk/gcloud_main.py", line 186, in main
    gcloud_cli.Execute()
  File "/home/devilunraveled/GoogleCloud/google-cloud-sdk/lib/googlecloudsdk/calliope/cli.py", line 1013, in Execute
    self._HandleAllErrors(exc, command_path_string, specified_arg_names)
  File "/home/devilunraveled/GoogleCloud/google-cloud-sdk/lib/googlecloudsdk/calliope/cli.py", line 1050, in _HandleAllErrors
    exceptions.HandleError(exc, command_path_string, self.__known_error_handler)
  File "/home/devilunraveled/GoogleCloud/google-cloud-sdk/lib/googlecloudsdk/calliope/exceptions.py", line 557, in HandleError
    core_exceptions.reraise(exc)
  File "/home/devilunraveled/GoogleCloud/google-cloud-sdk/lib/googlecloudsdk/core/exceptions.py", line 146, in reraise
    six.reraise(type(exc_value), exc_value, tb)
  File "/home/devilunraveled/GoogleCloud/google-cloud-sdk/lib/third_party/six/__init__.py", line 719, in reraise
    raise value
  File "/home/devilunraveled/GoogleCloud/google-cloud-sdk/lib/googlecloudsdk/calliope/cli.py", line 987, in Execute
    resources = calliope_command.Run(cli=self, args=args)
  File "/home/devilunraveled/GoogleCloud/google-cloud-sdk/lib/googlecloudsdk/calliope/backend.py", line 807, in Run
    resources = command_instance.Run(args)
  File "/home/devilunraveled/GoogleCloud/google-cloud-sdk/lib/surface/init.py", line 160, in Run
    if not self._PickAccount(
  File "/home/devilunraveled/GoogleCloud/google-cloud-sdk/lib/surface/init.py", line 232, in _PickAccount
    if not self._RunCmd(['auth', 'login'],
  File "/home/devilunraveled/GoogleCloud/google-cloud-sdk/lib/surface/init.py", line 525, in _RunCmd
    self.ExecuteCommandDoNotUse(args))
  File "/home/devilunraveled/GoogleCloud/google-cloud-sdk/lib/googlecloudsdk/calliope/base.py", line 624, in ExecuteCommandDoNotUse
    return self._cli_power_users_only.Execute(args, call_arg_complete=False)
  File "/home/devilunraveled/GoogleCloud/google-cloud-sdk/lib/googlecloudsdk/calliope/cli.py", line 1013, in Execute
    self._HandleAllErrors(exc, command_path_string, specified_arg_names)
  File "/home/devilunraveled/GoogleCloud/google-cloud-sdk/lib/googlecloudsdk/calliope/cli.py", line 1050, in _HandleAllErrors
    exceptions.HandleError(exc, command_path_string, self.__known_error_handler)
  File "/home/devilunraveled/GoogleCloud/google-cloud-sdk/lib/googlecloudsdk/calliope/exceptions.py", line 557, in HandleError
    core_exceptions.reraise(exc)
  File "/home/devilunraveled/GoogleCloud/google-cloud-sdk/lib/googlecloudsdk/core/exceptions.py", line 146, in reraise
    six.reraise(type(exc_value), exc_value, tb)
  File "/home/devilunraveled/GoogleCloud/google-cloud-sdk/lib/third_party/six/__init__.py", line 719, in reraise
    raise value
  File "/home/devilunraveled/GoogleCloud/google-cloud-sdk/lib/googlecloudsdk/calliope/cli.py", line 987, in Execute
    resources = calliope_command.Run(cli=self, args=args)
  File "/home/devilunraveled/GoogleCloud/google-cloud-sdk/lib/googlecloudsdk/calliope/backend.py", line 807, in Run
    resources = command_instance.Run(args)
  File "/home/devilunraveled/GoogleCloud/google-cloud-sdk/lib/surface/auth/login.py", line 331, in Run
    creds = auth_util.DoInstalledAppBrowserFlowGoogleAuth(
  File "/home/devilunraveled/GoogleCloud/google-cloud-sdk/lib/googlecloudsdk/api_lib/auth/util.py", line 332, in DoInstalledAppBrowserFlowGoogleAuth
    user_creds = BrowserFlowWithNoBrowserFallbackRunner(
  File "/home/devilunraveled/GoogleCloud/google-cloud-sdk/lib/googlecloudsdk/api_lib/auth/util.py", line 144, in Run
    return self._flow.Run(**kwargs)
  File "/home/devilunraveled/GoogleCloud/google-cloud-sdk/lib/googlecloudsdk/core/credentials/flow.py", line 237, in Run
    return self._Run(**kwargs)
  File "/home/devilunraveled/GoogleCloud/google-cloud-sdk/lib/googlecloudsdk/core/credentials/flow.py", line 336, in _Run
    self.fetch_token(
  File "/home/devilunraveled/GoogleCloud/google-cloud-sdk/lib/third_party/google_auth_oauthlib/flow.py", line 300, in fetch_token
    return self.oauth2session.fetch_token(self.client_config["token_uri"], **kwargs)
  File "/home/devilunraveled/GoogleCloud/google-cloud-sdk/lib/third_party/requests_oauthlib/oauth2_session.py", line 345, in fetch_token
    self._client.parse_request_body_response(r.text, scope=self.scope)
  File "/home/devilunraveled/GoogleCloud/google-cloud-sdk/lib/third_party/oauthlib/oauth2/rfc6749/clients/base.py", line 451, in parse_request_body_response
    self.token = parse_token_response(body, scope=scope)
  File "/home/devilunraveled/GoogleCloud/google-cloud-sdk/lib/third_party/oauthlib/oauth2/rfc6749/parameters.py", line 435, in parse_token_response
    validate_token_parameters(params)
  File "/home/devilunraveled/GoogleCloud/google-cloud-sdk/lib/third_party/oauthlib/oauth2/rfc6749/parameters.py", line 442, in validate_token_parameters
    raise_from_error(params.get('error'), params)
  File "/home/devilunraveled/GoogleCloud/google-cloud-sdk/lib/third_party/oauthlib/oauth2/rfc6749/errors.py", line 406, in raise_from_error
    raise cls(**kwargs)
oauthlib.oauth2.rfc6749.errors.InvalidGrantError: (invalid_grant) Bad Request
2023-10-10 01:37:43,632 ERROR    root            gcloud crashed (InvalidGrantError): (invalid_grant) Bad Request
2023-10-10 01:37:43,632 INFO     ___FILE_ONLY___ 
If you would like to report this issue, please run the following command:

2023-10-10 01:37:43,632 INFO     ___FILE_ONLY___   gcloud feedback

2023-10-10 01:37:43,632 INFO     ___FILE_ONLY___ 
To check gcloud for common problems, please run the following command:

2023-10-10 01:37:43,632 INFO     ___FILE_ONLY___   gcloud info --run-diagnostics

